<?xml version="1.0" ?>
<!-- =================================================================================== -->
<!-- |    This document was autogenerated by xacro from indy.urdf.xacro                | -->
<!-- |    EDITING THIS FILE BY HAND IS NOT RECOMMENDED                                 | -->
<!-- =================================================================================== -->
<robot name="indy">
  <mujoco>
    <compiler meshdir="../assets" balanceinertia="true"/>
  </mujoco>

  <material name="black">
    <color rgba="0.0 0.0 0.0 1.0"/>
  </material>
  <material name="blue">
    <color rgba="0.0 0.0 0.8 1.0"/>
  </material>
  <material name="green">
    <color rgba="0.0 0.8 0.0 1.0"/>
  </material>
  <material name="icon_green">
    <color rgba="0.596078431372549 0.7764705882352941 0.3843137254901961 1.0"/>
  </material>
  <material name="icon_grey">
    <color rgba="0.2 0.2 0.2 1.0"/>
  </material>
  <material name="indy_white">
    <color rgba="0.8941176470588236 0.8941176470588236 0.8941176470588236 1.0"/>
  </material>
  <material name="grey">
    <color rgba="0.2 0.2 0.2 1.0"/>
  </material>
  <material name="orange">
    <color rgba="1.0 0.4235294117647059 0.0392156862745098 1.0"/>
  </material>
  <material name="brown">
    <color rgba="0.8705882352941177 0.8117647058823529 0.7647058823529411 1.0"/>
  </material>
  <material name="red">
    <color rgba="0.8 0.0 0.0 1.0"/>
  </material>
  <material name="white">
    <color rgba="1.0 1.0 1.0 1.0"/>
  </material>
  <material name="metal">
    <color rgba="0.768627450980392 0.749019607843137 0.729411764705882 1"/>
  </material>
  <material name="metal_grey">
    <color rgba="0.501960784313725 0.501960784313725 0.501960784313725 1"/>
  </material>
  <material name="metal_white">
    <color rgba="0.866666666666667 0.866666666666667 0.890196078431373 1"/>
  </material>
  <link name="world"/>
  <link name="link0">
    <visual>
      <origin rpy="0 0 0" xyz="0 0 0"/>
      <geometry>
        <mesh filename="indy7/Indy7_0.stl"/>
      </geometry>
      <material name="indy_white"/>
    </visual>
    <collision>
      <origin rpy="0 0 0" xyz="0 0 0"/>
      <geometry>
        <mesh filename="indy7/Indy7_0.stl"/>
      </geometry>
    </collision>
    <inertial>
      <mass value="1.6703078"/>
      <origin rpy="0 0 0" xyz="0.00131966                             -2.18e-06                             0.03212832"/>
      <inertia ixx="0.00661309" ixy="1.83e-06" ixz="2.695e-05" iyy="0.00644765" iyz="-2.7e-07" izz="0.0079209"/>
    </inertial>
  </link>
  <link name="link1">
    <visual>
      <origin rpy="0 0 0" xyz="0 0 0"/>
      <geometry>
        <mesh filename="indy7/Indy7_1.stl"/>
      </geometry>
      <material name="indy_white"/>
    </visual>
    <collision>
      <origin rpy="0 0 0" xyz="0 0 0"/>
      <geometry>
        <mesh filename="indy7/Indy7_1.stl"/>
      </geometry>
    </collision>
    <inertial>
      <mass value="11.44444535"/>
      <origin rpy="0 0 0" xyz="-0.00023749                             -0.04310313                             0.13245396"/>
      <inertia ixx="0.35065005" ixy="0.00011931" ixz="-0.00037553" iyy="0.304798" iyz="-0.10984447" izz="0.06003147"/>
    </inertial>
  </link>
  <link name="link2">
    <visual>
      <origin rpy="0 0 0" xyz="0 0 0"/>
      <geometry>
        <mesh filename="indy7/Indy7_2.stl"/>
      </geometry>
      <material name="indy_white"/>
    </visual>
    <collision>
      <origin rpy="0 0 0" xyz="0 0 0"/>
      <geometry>
        <mesh filename="indy7/Indy7_2.stl"/>
      </geometry>
    </collision>
    <inertial>
      <mass value="5.84766553"/>
      <origin rpy="0 0 0" xyz="-0.29616699                             2.254e-05                             0.04483069"/>
      <inertia ixx="0.03599743" ixy="-4.693e-05" ixz="-0.05240346" iyy="0.72293306" iyz="1.76e-06" izz="0.70024119"/>
    </inertial>
  </link>
  <link name="link3">
    <visual>
      <origin rpy="0 0 0" xyz="0 0 0"/>
      <geometry>
        <mesh filename="indy7/Indy7_3.stl"/>
      </geometry>
      <material name="indy_white"/>
    </visual>
    <collision>
      <origin rpy="0 0 0" xyz="0 0 0"/>
      <geometry>
        <mesh filename="indy7/Indy7_3.stl"/>
      </geometry>
    </collision>
    <inertial>
      <mass value="2.68206064"/>
      <origin rpy="0 0 0" xyz="-0.16804016                             0.00021421                             -0.07000383"/>
      <inertia ixx="0.0161721" ixy="-0.00011817" ixz="0.03341882" iyy="0.11364055" iyz="-4.371e-05" izz="0.10022522"/>
    </inertial>
  </link>
  <link name="link4">
    <visual>
      <origin rpy="0 0 0" xyz="0 0 0"/>
      <geometry>
        <mesh filename="indy7/Indy7_4.stl"/>
      </geometry>
      <material name="indy_white"/>
    </visual>
    <collision>
      <origin rpy="0 0 0" xyz="0 0 0"/>
      <geometry>
        <mesh filename="indy7/Indy7_4.stl"/>
      </geometry>
    </collision>
    <inertial>
      <mass value="2.12987371"/>
      <origin rpy="0 0 0" xyz="-0.00026847                             -0.0709844                             0.07649128"/>
      <inertia ixx="0.02798891" ixy="3.893e-05" ixz="-4.768e-05" iyy="0.01443076" iyz="-0.01266296" izz="0.01496211"/>
    </inertial>
  </link>
  <link name="link5">
    <visual>
      <origin rpy="0 0 0" xyz="0 0 0"/>
      <geometry>
        <mesh filename="indy7/Indy7_5.stl"/>
      </geometry>
      <material name="indy_white"/>
    </visual>
    <collision>
      <origin rpy="0 0 0" xyz="0 0 0"/>
      <geometry>
        <mesh filename="indy7/Indy7_5.stl"/>
      </geometry>
    </collision>
    <inertial>
      <mass value="2.22412271"/>
      <origin rpy="0 0 0" xyz="-0.09796232                             -0.00023114                             0.06445892"/>
      <inertia ixx="0.01105297" ixy="5.517e-05" ixz="-0.01481977" iyy="0.03698291" iyz="-3.74e-05" izz="0.02754795"/>
    </inertial>
  </link>
  <link name="link6">
    <visual>
      <origin rpy="0 0 0" xyz="0 0 0"/>
      <geometry>
        <mesh filename="indy7/Indy7_6.stl"/>
      </geometry>
      <material name="indy_white"/>
    </visual>
    <collision>
      <origin rpy="0 0 0" xyz="0 0 0"/>
      <geometry>
        <mesh filename="indy7/Indy7_6.stl"/>
      </geometry>
    </collision>
    <inertial>
      <mass value="0.38254932"/>
      <origin rpy="0 0 0" xyz="8.147e-05                             -0.00046556                             0.03079097"/>
      <inertia ixx="0.00078982" ixy="-3.4e-07" ixz="8.3e-07" iyy="0.00079764" iyz="-5.08e-06" izz="0.00058319"/>
    </inertial>
  </link>
  <link name="tcp"/>
  <joint name="global" type="fixed">
    <origin rpy="0 0 0" xyz="0 0 0"/>
    <parent link="world"/>
    <child link="link0"/>
  </joint>
  <joint name="joint0" type="revolute">
    <parent link="link0"/>
    <child link="link1"/>
    <origin rpy="0                         0                         0" xyz="0                          0                          0.0775"/>
    <axis xyz="0 0 1"/>
    <dynamics damping="0.1" friction="10.0"/>
    <limit effort="431.97" lower="-3.0543261909900767" upper="3.0543261909900767" velocity="2.6179938779914944"/>
  </joint>
  <joint name="joint1" type="revolute">
    <parent link="link1"/>
    <child link="link2"/>
    <origin rpy="1.570796327                         1.570796327                         0" xyz="0                          -0.109                          0.222"/>
    <axis xyz="0 0 1"/>
    <dynamics damping="0.1" friction="10.0"/>
    <limit effort="431.97" lower="-3.0543261909900767" upper="3.0543261909900767" velocity="2.6179938779914944"/>
  </joint>
  <joint name="joint2" type="revolute">
    <parent link="link2"/>
    <child link="link3"/>
    <origin rpy="0                         0                         0" xyz="-0.45                          0                          -0.0305"/>
    <axis xyz="0 0 1"/>
    <dynamics damping="0.1" friction="10.0"/>
    <limit effort="197.23" lower="-3.0543261909900767" upper="3.0543261909900767" velocity="2.6179938779914944"/>
  </joint>
  <joint name="joint3" type="revolute">
    <parent link="link3"/>
    <child link="link4"/>
    <origin rpy="-1.570796327                         0                         1.570796327" xyz="-0.267                          0                          -0.075"/>
    <axis xyz="0 0 1"/>
    <dynamics damping="0.1" friction="10.0"/>
    <limit effort="79.79" lower="-3.0543261909900767" upper="3.0543261909900767" velocity="3.141592653589793"/>
  </joint>
  <joint name="joint4" type="revolute">
    <parent link="link4"/>
    <child link="link5"/>
    <origin rpy="1.570796327                         1.570796327                         0" xyz="0                          -0.114                          0.083"/>
    <axis xyz="0 0 1"/>
    <dynamics damping="0.1" friction="10.0"/>
    <limit effort="79.79" lower="-3.0543261909900767" upper="3.0543261909900767" velocity="3.141592653589793"/>
  </joint>
  <joint name="joint5" type="revolute">
    <parent link="link5"/>
    <child link="link6"/>
    <origin rpy="-1.570796327                         0                         1.570796327" xyz="-0.168                          0                          0.069"/>
    <axis xyz="0 0 1"/>
    <dynamics damping="0.1" friction="10.0"/>
    <limit effort="79.79" lower="-3.7524578917878086" upper="3.7524578917878086" velocity="3.141592653589793"/>
  </joint>
  <joint name="tcp" type="fixed">
    <parent link="link6"/>
    <child link="tcp"/>
    <origin rpy="0.0                         0.0                         0.0" xyz="0.0                          0.0                          0.06"/>
  </joint>
  <ros2_control name="indy" type="system">
    <hardware>
      <plugin>fake_components/GenericSystem</plugin>
      <param name="state_following_offset">0.0</param>
    </hardware>
    <joint name="joint0">
      <command_interface name="position">
        <param name="min">-6.283185</param>
        <param name="max">6.283185</param>
      </command_interface>
      <command_interface name="velocity">
        <param name="min">-3.15</param>
        <param name="max">3.15</param>
      </command_interface>
      <state_interface name="position">
        <param name="initial_value">0.0</param>
      </state_interface>
      <state_interface name="velocity">
        <param name="initial_value">0.0</param>
      </state_interface>
      <state_interface name="effort">
        <param name="initial_value">0.0</param>
      </state_interface>
    </joint>
    <joint name="joint1">
      <command_interface name="position">
        <param name="min">-6.283185</param>
        <param name="max">6.283185</param>
      </command_interface>
      <command_interface name="velocity">
        <param name="min">-3.15</param>
        <param name="max">3.15</param>
      </command_interface>
      <state_interface name="position">
        <param name="initial_value">0.0</param>
      </state_interface>
      <state_interface name="velocity">
        <param name="initial_value">0.0</param>
      </state_interface>
      <state_interface name="effort">
        <param name="initial_value">0.0</param>
      </state_interface>
    </joint>
    <joint name="joint2">
      <command_interface name="position">
        <param name="min">-6.283185</param>
        <param name="max">6.283185</param>
      </command_interface>
      <command_interface name="velocity">
        <param name="min">-3.15</param>
        <param name="max">3.15</param>
      </command_interface>
      <state_interface name="position">
        <param name="initial_value">-1.57</param>
      </state_interface>
      <state_interface name="velocity">
        <param name="initial_value">0.0</param>
      </state_interface>
      <state_interface name="effort">
        <param name="initial_value">0.0</param>
      </state_interface>
    </joint>
    <joint name="joint3">
      <command_interface name="position">
        <param name="min">-6.283185</param>
        <param name="max">6.283185</param>
      </command_interface>
      <command_interface name="velocity">
        <param name="min">-3.15</param>
        <param name="max">3.15</param>
      </command_interface>
      <state_interface name="position">
        <param name="initial_value">0.0</param>
      </state_interface>
      <state_interface name="velocity">
        <param name="initial_value">0.0</param>
      </state_interface>
      <state_interface name="effort">
        <param name="initial_value">0.0</param>
      </state_interface>
    </joint>
    <joint name="joint4">
      <command_interface name="position">
        <param name="min">-6.283185</param>
        <param name="max">6.283185</param>
      </command_interface>
      <command_interface name="velocity">
        <param name="min">-3.15</param>
        <param name="max">3.15</param>
      </command_interface>
      <state_interface name="position">
        <param name="initial_value">-1.57</param>
      </state_interface>
      <state_interface name="velocity">
        <param name="initial_value">0.0</param>
      </state_interface>
      <state_interface name="effort">
        <param name="initial_value">0.0</param>
      </state_interface>
    </joint>
    <joint name="joint5">
      <command_interface name="position">
        <param name="min">-6.283185</param>
        <param name="max">6.283185</param>
      </command_interface>
      <command_interface name="velocity">
        <param name="min">-3.15</param>
        <param name="max">3.15</param>
      </command_interface>
      <state_interface name="position">
        <param name="initial_value">0.0</param>
      </state_interface>
      <state_interface name="velocity">
        <param name="initial_value">0.0</param>
      </state_interface>
      <state_interface name="effort">
        <param name="initial_value">0.0</param>
      </state_interface>
    </joint>
  </ros2_control>
  <!-- Add URDF transmission elements (for ros_control) -->
  <!-- <xacro:indy_transmission prefix="${prefix}" hw_interface="${transmission_hw_interface}" indy_type="${indy_type}"/> -->
  <!-- MARK7_REAL_START -->
  <joint name="mark7_mount_joint" type="fixed">
    <parent link="link6" />
    <child link="mark7_base_link" />
    <origin xyz="0.000 0.000 0.085" rpy="0 0 0" />
  </joint>







  <material name="silver">
    <color rgba="0.700 0.700 0.700 1.000"/>
  </material>
  
  
  
  
  
  
  
  
  
  
  
  
  
  
  
  
  
  
  
  <link name="mark7_base_link">
    <inertial>
      <origin rpy="0 0 0" xyz="0.001555 -0.004795 0.047623"/>
      <mass value="0.35"/>
      <inertia ixx="0.000718" ixy="-1.4e-05" ixz="1.8e-05" iyy="0.000888" iyz="0.000117" izz="0.000438"/>
    </inertial>
    <visual>
      <origin rpy="0 0 0" xyz="0 0 0"/>
      <geometry>
        <mesh filename="mark7/base_link.stl" scale="0.001 0.001 0.001"/>
      </geometry>
      <material name="silver"/>
    </visual>
    <collision>
      <origin rpy="0 0 0" xyz="0 0 0"/>
      <geometry>
        <mesh filename="mark7/base_link.stl" scale="0.001 0.001 0.001"/>
      </geometry>
    </collision>
  </link>
  <link name="mark7_pinky_bottom_1">
    <inertial>
      <mass value="0.03"/>
      <inertia ixx="0.000001" ixy="0.0" ixz="0.0" iyy="0.000001" iyz="0.0" izz="0.000001"/>
    </inertial>
    <visual>
      <origin rpy="0 0 0" xyz="-0.031928 0.005928 -0.078169"/>
      <geometry>
        <mesh filename="mark7/pinky_bottom_1.stl" scale="0.001 0.001 0.001"/>
      </geometry>
      <material name="silver"/>
    </visual>
    <collision>
      <origin rpy="0 0 0" xyz="-0.031928 0.005928 -0.078169"/>
      <geometry>
        <mesh filename="mark7/pinky_bottom_1.stl" scale="0.001 0.001 0.001"/>
      </geometry>
    </collision>
  </link>
  <link name="mark7_pinky_top_1">
    <inertial>
      <mass value="0.03"/>
      <inertia ixx="0.000001" ixy="0.0" ixz="0.0" iyy="0.000001" iyz="0.0" izz="0.000001"/>
    </inertial>
    <visual>
      <origin rpy="0 0 0" xyz="-0.037439 -0.000714 -0.107655"/>
      <geometry>
        <mesh filename="mark7/pinky_top_1.stl" scale="0.001 0.001 0.001"/>
      </geometry>
      <material name="silver"/>
    </visual>
    <collision>
      <origin rpy="0 0 0" xyz="-0.037439 -0.000714 -0.107655"/>
      <geometry>
        <mesh filename="mark7/pinky_top_1.stl" scale="0.001 0.001 0.001"/>
      </geometry>
    </collision>
  </link>
  <link name="mark7_ringer_bottom_1">
    <inertial>
      <mass value="0.04"/>
      <inertia ixx="0.000001" ixy="0.0" ixz="0.0" iyy="0.000001" iyz="0.0" izz="0.000001"/>
    </inertial>
    <visual>
      <origin rpy="0 0 0" xyz="-0.011471 0.009409 -0.085649"/>
      <geometry>
        <mesh filename="mark7/ringer_bottom_1.stl" scale="0.001 0.001 0.001"/>
      </geometry>
      <material name="silver"/>
    </visual>
    <collision>
      <origin rpy="0 0 0" xyz="-0.011471 0.009409 -0.085649"/>
      <geometry>
        <mesh filename="mark7/ringer_bottom_1.stl" scale="0.001 0.001 0.001"/>
      </geometry>
    </collision>
  </link>
  <link name="mark7_ringer_top_1">
    <inertial>
      <mass value="0.03"/>
      <inertia ixx="0.000001" ixy="0.0" ixz="0.0" iyy="0.000001" iyz="0.0" izz="0.000001"/>
    </inertial>
    <visual>
      <origin rpy="0 0 0" xyz="-0.015717 0.00084 -0.123103"/>
      <geometry>
        <mesh filename="mark7/ringer_top_1.stl" scale="0.001 0.001 0.001"/>
      </geometry>
      <material name="silver"/>
    </visual>
    <collision>
      <origin rpy="0 0 0" xyz="-0.015717 0.00084 -0.123103"/>
      <geometry>
        <mesh filename="mark7/ringer_top_1.stl" scale="0.001 0.001 0.001"/>
      </geometry>
    </collision>
  </link>
  <link name="mark7_middle_bottom_1">
    <inertial>
      <mass value="0.05"/>
      <inertia ixx="0.000001" ixy="0.0" ixz="0.0" iyy="0.000001" iyz="0.0" izz="0.000001"/>
    </inertial>
    <visual>
      <origin rpy="0 0 0" xyz="0.008513 0.011057 -0.092109"/>
      <geometry>
        <mesh filename="mark7/middle_bottom_1.stl" scale="0.001 0.001 0.001"/>
      </geometry>
      <material name="silver"/>
    </visual>
    <collision>
      <origin rpy="0 0 0" xyz="0.008513 0.011057 -0.092109"/>
      <geometry>
        <mesh filename="mark7/middle_bottom_1.stl" scale="0.001 0.001 0.001"/>
      </geometry>
    </collision>
  </link>
  <link name="mark7_middle_top_1">
    <inertial>
      <mass value="0.03"/>
      <inertia ixx="0.000001" ixy="0.0" ixz="0.0" iyy="0.000001" iyz="0.0" izz="0.000001"/>
    </inertial>
    <visual>
      <origin rpy="0 0 0" xyz="0.006949 0.002365 -0.133647"/>
      <geometry>
        <mesh filename="mark7/middle_top_1.stl" scale="0.001 0.001 0.001"/>
      </geometry>
      <material name="silver"/>
    </visual>
    <collision>
      <origin rpy="0 0 0" xyz="0.006949 0.002365 -0.133647"/>
      <geometry>
        <mesh filename="mark7/middle_top_1.stl" scale="0.001 0.001 0.001"/>
      </geometry>
    </collision>
  </link>
  <link name="mark7_index_bottom_1">
    <inertial>
      <mass value="0.04"/>
      <inertia ixx="0.000001" ixy="0.0" ixz="0.0" iyy="0.000001" iyz="0.0" izz="0.000001"/>
    </inertial>
    <visual>
      <origin rpy="0 0 0" xyz="0.030299 0.008352 -0.089777"/>
      <geometry>
        <mesh filename="mark7/index_bottom_1.stl" scale="0.001 0.001 0.001"/>
      </geometry>
      <material name="silver"/>
    </visual>
    <collision>
      <origin rpy="0 0 0" xyz="0.030299 0.008352 -0.089777"/>
      <geometry>
        <mesh filename="mark7/index_bottom_1.stl" scale="0.001 0.001 0.001"/>
      </geometry>
    </collision>
  </link>
  <link name="mark7_index_top_1">
    <inertial>
      <mass value="0.03"/>
      <inertia ixx="0.000001" ixy="0.0" ixz="0.0" iyy="0.000001" iyz="0.0" izz="0.000001"/>
    </inertial>
    <visual>
      <origin rpy="0 0 0" xyz="0.032614 0.001276 -0.127706"/>
      <geometry>
        <mesh filename="mark7/index_top_1.stl" scale="0.001 0.001 0.001"/>
      </geometry>
      <material name="silver"/>
    </visual>
    <collision>
      <origin rpy="0 0 0" xyz="0.032614 0.001276 -0.127706"/>
      <geometry>
        <mesh filename="mark7/index_top_1.stl" scale="0.001 0.001 0.001"/>
      </geometry>
    </collision>
  </link>
  <link name="mark7_thumb_bottom_1">
    <inertial>
      <mass value="0.05"/>
      <inertia ixx="0.000001" ixy="0.0" ixz="0.0" iyy="0.000001" iyz="0.0" izz="0.000001"/>
    </inertial>
    <visual>
      <origin rpy="0 0 0" xyz="0.007376 -0.005575 -0.034463"/>
      <geometry>
        <mesh filename="mark7/thumb_bottom_1.stl" scale="0.001 0.001 0.001"/>
      </geometry>
      <material name="silver"/>
    </visual>
    <collision>
      <origin rpy="0 0 0" xyz="0.007376 -0.005575 -0.034463"/>
      <geometry>
        <mesh filename="mark7/thumb_bottom_1.stl" scale="0.001 0.001 0.001"/>
      </geometry>
    </collision>
  </link>
  <link name="mark7_thumb_middle_1">
    <inertial>
      <mass value="0.04"/>
      <inertia ixx="0.000001" ixy="0.0" ixz="0.0" iyy="0.000001" iyz="0.0" izz="0.000001"/>
    </inertial>
    <visual>
      <origin rpy="0 0 0" xyz="0.036417 -0.014922 -0.033958"/>
      <geometry>
        <mesh filename="mark7/thumb_middle_1.stl" scale="0.001 0.001 0.001"/>
      </geometry>
      <material name="silver"/>
    </visual>
    <collision>
      <origin rpy="0 0 0" xyz="0.036417 -0.014922 -0.033958"/>
      <geometry>
        <mesh filename="mark7/thumb_middle_1.stl" scale="0.001 0.001 0.001"/>
      </geometry>
    </collision>
  </link>
  <link name="mark7_thumb_top_1">
    <inertial>
      <mass value="0.05"/>
      <inertia ixx="0.000001" ixy="0.0" ixz="0.0" iyy="0.000001" iyz="0.0" izz="0.000001"/>
    </inertial>
    <visual>
      <origin rpy="0 0 0" xyz="0.05907 -0.016082 -0.041644"/>
      <geometry>
        <mesh filename="mark7/thumb_top_1.stl" scale="0.001 0.001 0.001"/>
      </geometry>
      <material name="silver"/>
    </visual>
    <collision>
      <origin rpy="0 0 0" xyz="0.05907 -0.016082 -0.041644"/>
      <geometry>
        <mesh filename="mark7/thumb_top_1.stl" scale="0.001 0.001 0.001"/>
      </geometry>
    </collision>
  </link>
  <joint name="mark7_base_pinky" type="revolute">
    <origin rpy="0 0 0" xyz="0.031928 -0.005928 0.078169"/>
    <parent link="mark7_base_link"/>
    <child link="mark7_pinky_bottom_1"/>
    <axis xyz="-0.972127 -0.033995 0.231975"/>
    <limit effort="20" lower="0.0" upper="1.396" velocity="2.0"/>
  </joint>
  <joint name="mark7_pinky_bottom_top" type="revolute">
    <origin rpy="0 0 0" xyz="0.005511 0.006642 0.029486"/>
    <parent link="mark7_pinky_bottom_1"/>
    <child link="mark7_pinky_top_1"/>
    <axis xyz="-0.972127 -0.033995 0.231975"/>
    <mimic joint="mark7_base_pinky" multiplier="1.0" offset="0"/>
    <limit effort="0" lower="0.0" upper="1.396" velocity="2.0"/>
  </joint>
  <joint name="mark7_base_ringer" type="revolute">
    <origin rpy="0 0 0" xyz="0.011471 -0.009409 0.085649"/>
    <parent link="mark7_base_link"/>
    <child link="mark7_ringer_bottom_1"/>
    <axis xyz="-0.991562 -0.005724 0.129511"/>
    <limit effort="20" lower="0.0" upper="1.396" velocity="2.0"/>
  </joint>
  <joint name="mark7_ringer_bottom_top_rev" type="revolute">
    <origin rpy="0 0 0" xyz="0.004246 0.008569 0.037454"/>
    <parent link="mark7_ringer_bottom_1"/>
    <child link="mark7_ringer_top_1"/>
    <axis xyz="-0.991562 -0.005724 0.129511"/>
    <mimic joint="mark7_base_ringer" multiplier="1.0" offset="0"/>
    <limit effort="0" lower="0.0" upper="1.396" velocity="4.0"/>
  </joint>
  <joint name="mark7_base_middle" type="revolute">
    <origin rpy="0 0 0" xyz="-0.008513 -0.011057 0.092109"/>
    <parent link="mark7_base_link"/>
    <child link="mark7_middle_bottom_1"/>
    <axis xyz="-0.998722 0.009815 0.049588"/>
    <limit effort="20" lower="0.0" upper="1.396" velocity="2.0"/>
  </joint>
  <joint name="mark7_middle_bottom_top_rev" type="revolute">
    <origin rpy="0 0 0" xyz="0.001564 0.008692 0.041538"/>
    <parent link="mark7_middle_bottom_1"/>
    <child link="mark7_middle_top_1"/>
    <axis xyz="-0.998722 0.009815 0.049588"/>
    <mimic joint="mark7_base_middle" multiplier="1.0" offset="0"/>
    <limit effort="0" lower="0.0" upper="1.396" velocity="4.0"/>
  </joint>
  <joint name="mark7_base_index" type="revolute">
    <origin rpy="0 0 0" xyz="-0.030299 -0.008352 0.089777"/>
    <parent link="mark7_base_link"/>
    <child link="mark7_index_bottom_1"/>
    <axis xyz="-0.997898 0.03262 -0.055994"/>
    <limit effort="20" lower="0.0" upper="1.396" velocity="2.0"/>
  </joint>
  <joint name="mark7_index_bottom_top_rev" type="revolute">
    <origin rpy="0 0 0" xyz="-0.002315 0.007076 0.037929"/>
    <parent link="mark7_index_bottom_1"/>
    <child link="mark7_index_top_1"/>
    <axis xyz="-0.997898 0.03262 -0.055994"/>
    <mimic joint="mark7_base_index" multiplier="1.0" offset="0"/>
    <limit effort="0" lower="0.0" upper="1.396" velocity="4.0"/>
  </joint>
  <joint name="mark7_base_thumb" type="revolute">
    <origin rpy="0 0 0" xyz="-0.007376 0.005575 0.034463"/>
    <parent link="mark7_base_link"/>
    <child link="mark7_thumb_bottom_1"/>
    <axis xyz="-0.995619 0.092558 -0.013228"/>
    <limit effort="25" lower="0.0" upper="1.396" velocity="2.0"/>
  </joint>
  <joint name="mark7_thumb_bottom_middle_rev" type="revolute">
    <origin rpy="0 0 0" xyz="-0.029041 0.009347 -0.000505"/>
    <parent link="mark7_thumb_bottom_1"/>
    <child link="mark7_thumb_middle_1"/>
    <axis xyz="-0.092166 -0.947763 0.305369"/>
    <limit effort="30" lower="-0.872665" upper="0.0" velocity="2.0"/>
  </joint>
  <joint name="mark7_thumb_middle_top_rev" type="revolute">
    <origin rpy="0 0 0" xyz="-0.022653 0.00116 0.007686"/>
    <parent link="mark7_thumb_middle_1"/>
    <child link="mark7_thumb_top_1"/>
    <axis xyz="-0.092165 -0.947763 0.305369"/>
    <mimic joint="mark7_thumb_bottom_middle_rev" multiplier="1.0" offset="0"/>
    <limit effort="0" lower="-0.872665" upper="0.0" velocity="2.0"/>
  </joint>
  
  
  
  
  
  
  
  
  


  <!-- MARK7_REAL_END -->

</robot>
